
<!-- sourced from https://github.com/lachlanhurst/balance-robot-mujoco-sim/blob/main/src/simulation -->

<mujoco model="balance">

	<worldbody>
		<body name="robot_body">
			<joint name="robot_body_joint" type="free"/>
			<geom size="0.05 0.0185 0.0855" pos="0 0 0.0995" type="box"/>
			<inertial pos="0 0.0 0.057" quat="0.707107 0 0 0.707107" mass="2.0" diaginertia="0.001311 0.0012568 0.000487"/>
			<site name="imu_site" pos="0 0 0.2" size="0.01" rgba="1 0 0 1"/>
			<body name="l_wheel" pos="-0.074 0 0.034">
				<inertial pos="0 0 0" quat="0.5 0.5 -0.5 0.5" mass="0.032" diaginertia="2.3e-05 1.3e-05 1.3e-05"/>
				<joint name="torso_l_wheel" type="hinge" pos="0 0 0" axis="-1 0 0" actuatorfrcrange="-5 5" damping="0.1"/>
				<geom name="l_wheel_geom" size="0.034 0.013" quat="0.707107 0 0.707107 0" type="cylinder" material="wheel_material"/>
			</body>
			<body name="r_wheel" pos="0.074 0 0.034">
				<inertial pos="0 0 0" quat="0.5 0.5 -0.5 0.5" mass="0.032" diaginertia="2.3e-05 1.3e-05 1.3e-05"/>
				<joint name="torso_r_wheel" type="hinge" pos="0 0 0" axis="1 0 0" actuatorfrcrange="-5 5" damping="0.1"/>
				<geom name="r_wheel_geom" size="0.034 0.013" quat="0.707107 0 0.707107 0" type="cylinder" material="wheel_material"/>
			</body>
		</body>
	</worldbody>

	<actuator>
		<motor name="motor_l_wheel" joint="torso_l_wheel" gear="0.25" ctrlrange="-100 100"/>
		<motor name="motor_r_wheel" joint="torso_r_wheel" gear="0.25" ctrlrange="-100 100"/>
	</actuator>

	<sensor>
		<!-- Gyroscope (angular velocity) on body -->
		<gyro name="imu_gyro" site="imu_site"/>
		<!-- Accelerometer -->
		<accelerometer name="imu_accel" site="imu_site"/>
	</sensor>

</mujoco>